--------------------
2018-08-24 17:17:47 - Exception on message: <karelia.Packet object at 0x7fa1a5d26d68>:
Traceback (most recent call last):
  File "main.py", line 202, in <module>
    for _key, value in saved_rolls[key]:
ValueError: too many values to unpack (expected 2)


